wandb: Starting wandb agent üïµÔ∏è
2021-11-09 15:57:49,703 - wandb.wandb_agent - INFO - Running runs: []
2021-11-09 15:57:50,096 - wandb.wandb_agent - INFO - Agent received command: run
2021-11-09 15:57:50,097 - wandb.wandb_agent - INFO - Agent starting run with config:
	confidence_scale: 0.3716431601639013
	target_entropy: -1.875378794211394
	use_entropy: True
2021-11-09 15:57:50,104 - wandb.wandb_agent - INFO - About to run command: python3 src/main.py --train --wandb
wandb: Currently logged in as: jjshoots (use `wandb login --relogin` to force relogin)
wandb: WARNING Ignored wandb.init() arg project when running a sweep
wandb: WARNING Ignored wandb.init() arg entity when running a sweep
-----------------------
Using Device cuda:0
-----------------------
wandb: wandb version 0.12.6 is available!  To upgrade, please run:
wandb:  $ pip install wandb --upgrade
2021-11-09 15:57:55,114 - wandb.wandb_agent - INFO - Running runs: ['589np1r7']
wandb: Tracking run with wandb version 0.12.0
wandb: Syncing run 29973
wandb:  View project at https://wandb.ai/jjshoots/UA3SAC_gym
wandb:  View sweep at https://wandb.ai/jjshoots/UA3SAC_gym/sweeps/l22tvp9t
wandb:  View run at https://wandb.ai/jjshoots/UA3SAC_gym/runs/589np1r7
wandb: Run data is saved locally in /home/taij/e2sac/wandb/run-20211109_155753-589np1r7
wandb: Run `wandb offline` to turn off syncing.
wandb: Network error (ReadTimeout), entering retry loop.
Error communicating with W&B: context deadline exceeded
500 response executing GraphQL.
{"error":"Error 1135: Can't create a new thread (errno 11); if you are not out of available memory, you can consult the manual for a possible OS-dependent bug"}

500 response executing GraphQL.
{"error":"Error 1135: Can't create a new thread (errno 11); if you are not out of available memory, you can consult the manual for a possible OS-dependent bug"}

500 response executing GraphQL.
{"errors":[{"message":"Error 1040: Too many connections","path":["agentHeartbeat"]}],"data":{"agentHeartbeat":null}}
wandb: ERROR Error while calling W&B API: Error 1040: Too many connections (<Response [500]>)
Retry attempt failed:
Traceback (most recent call last):
  File "/home/taij/.conda/envs/robocar/lib/python3.8/site-packages/wandb/sdk/lib/retry.py", line 102, in __call__
    result = self._call_fn(*args, **kwargs)
  File "/home/taij/.conda/envs/robocar/lib/python3.8/site-packages/wandb/sdk/internal/internal_api.py", line 136, in execute
    six.reraise(*sys.exc_info())
  File "/home/taij/.conda/envs/robocar/lib/python3.8/site-packages/six.py", line 719, in reraise
    raise value
  File "/home/taij/.conda/envs/robocar/lib/python3.8/site-packages/wandb/sdk/internal/internal_api.py", line 130, in execute
    return self.client.execute(*args, **kwargs)
  File "/home/taij/.conda/envs/robocar/lib/python3.8/site-packages/wandb/vendor/gql-0.2.0/gql/client.py", line 52, in execute
    result = self._get_result(document, *args, **kwargs)
  File "/home/taij/.conda/envs/robocar/lib/python3.8/site-packages/wandb/vendor/gql-0.2.0/gql/client.py", line 60, in _get_result
    return self.transport.execute(document, *args, **kwargs)
  File "/home/taij/.conda/envs/robocar/lib/python3.8/site-packages/wandb/vendor/gql-0.2.0/gql/transport/requests.py", line 39, in execute
    request.raise_for_status()
  File "/home/taij/.conda/envs/robocar/lib/python3.8/site-packages/requests/models.py", line 953, in raise_for_status
    raise HTTPError(http_error_msg, response=self)
requests.exceptions.HTTPError: 500 Server Error: Internal Server Error for url: https://api.wandb.ai/graphql
wandb: Network error (HTTPError), entering retry loop.
500 response executing GraphQL.
{"error":"Error 1040: Too many connections"}

500 response executing GraphQL.
{"error":"Error 1040: Too many connections"}

500 response executing GraphQL.
{"error":"Error 1040: Too many connections"}

500 response executing GraphQL.
{"error":"Error 1040: Too many connections"}

500 response executing GraphQL.
{"error":"Error 1040: Too many connections"}

/home/taij/.conda/envs/robocar/lib/python3.8/site-packages/torch/nn/functional.py:718: UserWarning: Named tensors and all their associated APIs are an experimental feature and subject to change. Please do not use them for anything important until they are released as stable. (Triggered internally at  /pytorch/c10/core/TensorImpl.h:1156.)
  return torch.max_pool2d(input, kernel_size, stride, padding, dilation, ceil_mode)
[34m[1mwandb[0m: Network error resolved after 0:05:20.777661, resuming normal operation.
wandb: Network error (ReadTimeout), entering retry loop.
500 response executing GraphQL.
{"error":"context deadline exceeded"}

[34m[1mwandb[0m: Network error resolved after 0:03:32.350317, resuming normal operation.
slurmstepd: *** JOB 4920326 ON zeus406 CANCELLED AT 2021-11-10T12:08:41 ***
/home/taij/.conda/envs/robocar/lib/python3.8/multiprocessing/resource_tracker.py:216: UserWarning: resource_tracker: There appear to be 6 leaked semaphore objects to clean up at shutdown
  warnings.warn('resource_tracker: There appear to be %d '
